Workbook

Sheet README
A1: Supplier Risk & Tariff-Impact Scorecard
A2: Datacenter hardware procurement scenario: GPU servers, network switches, PDU/MEP equipment
A4: How this workbook is organized
A5: Scorecard | B5: The primary deliverable: on-time rate, lead-time variability, landed cost, tariff exposure, defect rate, and a weighted composite risk score with RAG status, per supplier.
A6: Tariff_Scenario_Toggle | B6: Pick a tariff scenario from the dropdown and see landed spend recalculate per supplier in real time.
A7: Data_Quality_Log | B7: Live formulas auditing the raw export for duplicates and missing values prior to KPI calculation.
A8: Raw_Suppliers | B8: Supplier master data (3 suppliers across US, Mexico, and China).
A9: Raw_POs | B9: 344 purchase-order and shipment records simulating a Coupa export with intentional messiness for audit verification.
A10: Raw_Tariff_Ref | B10: Current (July 2026) effective tariff rates by supplier country and HS code.
A11: Raw_Tariff_Scenarios | B11: What-if scenarios feeding the dynamic dropdown on Tariff_Scenario_Toggle.
A12: Raw_Defects | B12: Quality/defect log linked to POs flagged with defects.
A14: Color legend
B15: Yellow fill: input cell / scenario selector (edit this)
B16: Green: Low risk (RAG)
B17: Yellow: Moderate risk (RAG)
B18: Red: High risk (RAG)
A20: Tariff assumptions (grounded in real July 2026 conditions)
A21: • China: 35% effective rate = 10% Section 122 surcharge + 25% Section 301 (source: CBP/USTR guidance as tracked April 2026).
A22: • Section 122's 10% surcharge is statutorily capped and sunsets ~Jul 24, 2026 unless renewed - modeled as a scenario.
A23: • Mexico: USMCA-qualifying goods carry a ~0% effective rate; non-qualifying goods pay MFN rate.
A24: • United States (domestic): 0% tariff exposure in all scenarios.

Sheet Scorecard
A1: Supplier Risk & Tariff-Impact Scorecard
A2: Weighted composite risk score: 30% delivery reliability, 20% lead-time volatility, 25% tariff exposure, 25% quality
A4: Supplier ID | B4: Supplier Name | C4: Country | D4: Delivered POs | E4: On Time POs | F4: On Time Rate | G4: Avg Lead Time Days | H4: Lead Time StDev Days | I4: Total Base Spend | J4: Total Landed Spend | K4: Tariff Exposure Pct | L4: Defect Rate Pct | M4: Avg Customs Days | N4: Composite Risk Score | O4: RAG Status
A5: SUP-001 | B5: =INDEX(Raw_Suppliers!$B$2:$B$4,MATCH(A5,Raw_Suppliers!$A$2:$A$4,0)) | C5: =INDEX(Raw_Suppliers!$C$2:$C$4,MATCH(A5,Raw_Suppliers!$A$2:$A$4,0)) | D5: =COUNTIFS(Raw_POs!$B$2:$B$345,A5,Raw_POs!$N$2:$N$345,"Delivered",Raw_POs!$W$2:$W$345,1) | E5: =SUMIFS(Raw_POs!$P$2:$P$345,Raw_POs!$B$2:$B$345,A5,Raw_POs!$W$2:$W$345,1) | F5: =IFERROR(E5/D5,0) | G5: =IFERROR(AVERAGEIFS(Raw_POs!$O$2:$O$345,Raw_POs!$B$2:$B$345,A5,Raw_POs!$N$2:$N$345,"Delivered",Raw_POs!$W$2:$W$345,1),0) | H5: =IFERROR(SQRT(SUMPRODUCT((Raw_POs!$B$2:$B$345=A5)*(Raw_POs!$N$2:$N$345="Delivered")*(Raw_POs!$W$2:$W$345=1)*(Raw_POs!$O$2:$O$345)^2)/D5-G5^2),0) | I5: =IFERROR(SUMIFS(Raw_POs!$T$2:$T$345,Raw_POs!$B$2:$B$345,A5,Raw_POs!$W$2:$W$345,1),0) | J5: =IFERROR(SUMIFS(Raw_POs!$V$2:$V$345,Raw_POs!$B$2:$B$345,A5,Raw_POs!$W$2:$W$345,1),0) | K5: =IFERROR((J5-I5)/I5,0) | L5: =IFERROR(COUNTIFS(Raw_POs!$B$2:$B$345,A5,Raw_POs!$N$2:$N$345,"Delivered",Raw_POs!$M$2:$M$345,"Y",Raw_POs!$W$2:$W$345,1)/D5,0) | M5: =IFERROR(AVERAGEIFS(Raw_POs!$L$2:$L$345,Raw_POs!$B$2:$B$345,A5,Raw_POs!$W$2:$W$345,1),0) | N5: =ROUND(0.30*(1-F5)*100+0.20*MIN(H5/20*100,100)+0.25*K5*100+0.25*L5*100,1) | O5: =IF(N5>=30,"Red",IF(N5>=15,"Yellow","Green"))
A6: SUP-002 | B6: =INDEX(Raw_Suppliers!$B$2:$B$4,MATCH(A6,Raw_Suppliers!$A$2:$A$4,0)) | C6: =INDEX(Raw_Suppliers!$C$2:$C$4,MATCH(A6,Raw_Suppliers!$A$2:$A$4,0)) | D6: =COUNTIFS(Raw_POs!$B$2:$B$345,A6,Raw_POs!$N$2:$N$345,"Delivered",Raw_POs!$W$2:$W$345,1) | E6: =SUMIFS(Raw_POs!$P$2:$P$345,Raw_POs!$B$2:$B$345,A6,Raw_POs!$W$2:$W$345,1) | F6: =IFERROR(E6/D6,0) | G6: =IFERROR(AVERAGEIFS(Raw_POs!$O$2:$O$345,Raw_POs!$B$2:$B$345,A6,Raw_POs!$N$2:$N$345,"Delivered",Raw_POs!$W$2:$W$345,1),0) | H6: =IFERROR(SQRT(SUMPRODUCT((Raw_POs!$B$2:$B$345=A6)*(Raw_POs!$N$2:$N$345="Delivered")*(Raw_POs!$W$2:$W$345=1)*(Raw_POs!$O$2:$O$345)^2)/D6-G6^2),0) | I6: =IFERROR(SUMIFS(Raw_POs!$T$2:$T$345,Raw_POs!$B$2:$B$345,A6,Raw_POs!$W$2:$W$345,1),0) | J6: =IFERROR(SUMIFS(Raw_POs!$V$2:$V$345,Raw_POs!$B$2:$B$345,A6,Raw_POs!$W$2:$W$345,1),0) | K6: =IFERROR((J6-I6)/I6,0) | L6: =IFERROR(COUNTIFS(Raw_POs!$B$2:$B$345,A6,Raw_POs!$N$2:$N$345,"Delivered",Raw_POs!$M$2:$M$345,"Y",Raw_POs!$W$2:$W$345,1)/D6,0) | M6: =IFERROR(AVERAGEIFS(Raw_POs!$L$2:$L$345,Raw_POs!$B$2:$B$345,A6,Raw_POs!$W$2:$W$345,1),0) | N6: =ROUND(0.30*(1-F6)*100+0.20*MIN(H6/20*100,100)+0.25*K6*100+0.25*L6*100,1) | O6: =IF(N6>=30,"Red",IF(N6>=15,"Yellow","Green"))
A7: SUP-003 | B7: =INDEX(Raw_Suppliers!$B$2:$B$4,MATCH(A7,Raw_Suppliers!$A$2:$A$4,0)) | C7: =INDEX(Raw_Suppliers!$C$2:$C$4,MATCH(A7,Raw_Suppliers!$A$2:$A$4,0)) | D7: =COUNTIFS(Raw_POs!$B$2:$B$345,A7,Raw_POs!$N$2:$N$345,"Delivered",Raw_POs!$W$2:$W$345,1) | E7: =SUMIFS(Raw_POs!$P$2:$P$345,Raw_POs!$B$2:$B$345,A7,Raw_POs!$W$2:$W$345,1) | F7: =IFERROR(E7/D7,0) | G7: =IFERROR(AVERAGEIFS(Raw_POs!$O$2:$O$345,Raw_POs!$B$2:$B$345,A7,Raw_POs!$N$2:$N$345,"Delivered",Raw_POs!$W$2:$W$345,1),0) | H7: =IFERROR(SQRT(SUMPRODUCT((Raw_POs!$B$2:$B$345=A7)*(Raw_POs!$N$2:$N$345="Delivered")*(Raw_POs!$W$2:$W$345=1)*(Raw_POs!$O$2:$O$345)^2)/D7-G7^2),0) | I7: =IFERROR(SUMIFS(Raw_POs!$T$2:$T$345,Raw_POs!$B$2:$B$345,A7,Raw_POs!$W$2:$W$345,1),0) | J7: =IFERROR(SUMIFS(Raw_POs!$V$2:$V$345,Raw_POs!$B$2:$B$345,A7,Raw_POs!$W$2:$W$345,1),0) | K7: =IFERROR((J7-I7)/I7,0) | L7: =IFERROR(COUNTIFS(Raw_POs!$B$2:$B$345,A7,Raw_POs!$N$2:$N$345,"Delivered",Raw_POs!$M$2:$M$345,"Y",Raw_POs!$W$2:$W$345,1)/D7,0) | M7: =IFERROR(AVERAGEIFS(Raw_POs!$L$2:$L$345,Raw_POs!$B$2:$B$345,A7,Raw_POs!$W$2:$W$345,1),0) | N7: =ROUND(0.30*(1-F7)*100+0.20*MIN(H7/20*100,100)+0.25*K7*100+0.25*L7*100,1) | O7: =IF(N7>=30,"Red",IF(N7>=15,"Yellow","Green"))
B8: TOTAL / BLENDED | D8: =SUM(D5:D7) | E8: =SUM(E5:E7) | F8: =IFERROR(E8/D8,0) | I8: =SUM(I5:I7) | J8: =SUM(J5:J7) | K8: =IFERROR((J8-I8)/I8,0)

Sheet Tariff_Scenario_Toggle
A1: Tariff Scenario Simulation Toggle
A2: Select a scenario from the dropdown to recalculate landed spend across all suppliers.
A4: Select Tariff Scenario: | B4: Current (Jul 2026) | D4: Adjustment Type: | E4: =IFERROR(INDEX(Raw_Tariff_Scenarios!$B$2:$B$6,MATCH($B$4,Raw_Tariff_Scenarios!$A$2:$A$6,0)),"") | F4: Adjustment Value: | G4: =IFERROR(INDEX(Raw_Tariff_Scenarios!$C$2:$C$6,MATCH($B$4,Raw_Tariff_Scenarios!$A$2:$A$6,0)),0) | H4: Scenario Description: | I4: =IFERROR(INDEX(Raw_Tariff_Scenarios!$D$2:$D$6,MATCH($B$4,Raw_Tariff_Scenarios!$A$2:$A$6,0)),"")
A6: Supplier ID | B6: Supplier Name | C6: Country | D6: Base Spend | E6: Current Effective Rate | F6: Scenario New Rate | G6: Scenario Landed Spend | H6: Delta vs Current Landed Spend
A7: =Scorecard!A5 | B7: =Scorecard!B5 | C7: =Scorecard!C5 | D7: =Scorecard!I5 | E7: =Scorecard!K5 | F7: =IF(C7="United States",0,IF($E$4="Additive",MAX(0,E7+$G$4),$G$4)) | G7: =D7*(1+F7) | H7: =G7-D7*(1+E7)
A8: =Scorecard!A6 | B8: =Scorecard!B6 | C8: =Scorecard!C6 | D8: =Scorecard!I6 | E8: =Scorecard!K6 | F8: =IF(C8="United States",0,IF($E$4="Additive",MAX(0,E8+$G$4),$G$4)) | G8: =D8*(1+F8) | H8: =G8-D8*(1+E8)
A9: =Scorecard!A7 | B9: =Scorecard!B7 | C9: =Scorecard!C7 | D9: =Scorecard!I7 | E9: =Scorecard!K7 | F9: =IF(C9="United States",0,IF($E$4="Additive",MAX(0,E9+$G$4),$G$4)) | G9: =D9*(1+F9) | H9: =G9-D9*(1+E9)
B10: TOTAL | D10: =SUM(D7:D9) | G10: =SUM(G7:G9) | H10: =SUM(H7:H9)

Sheet Data_Quality_Log
A1: Data Quality Audit: Raw_POs Export
A2: Live formulas auditing the raw Coupa export prior to KPI derivation.
A3: Audit Check | B3: Result
A4: Total PO rows in export | B4: =COUNTA(Raw_POs!A2:A345)
A5: Unique PO_IDs | B5: =SUMPRODUCT(1/COUNTIF(Raw_POs!A2:A345,Raw_POs!A2:A345))
A6: Duplicate row count (rows minus unique IDs) | B6: =B4-B5
A7: Rows missing Unit_Cost_USD (pending invoice reconciliation) | B7: =COUNTBLANK(Raw_POs!G2:G345)
A8: POs still In Transit (excluded from on-time/lead-time KPIs) | B8: =COUNTIF(Raw_POs!N2:N345,"In Transit")
A9: Inconsistent-case Incoterm values found | B9: =SUMPRODUCT(--(EXACT(Raw_POs!H2:H345,UPPER(Raw_POs!H2:H345))=FALSE))
A11: Data Cleaning & Deduplication Architecture
A12: The raw export simulates typical ERP portal noise (re-keyed orders and unreconciled invoice lines). Raw_POs column W (Is_First_Occurrence) flags duplicate entries to ensure every Scorecard formula, SQL query, and Python pipeline step computes strictly identical KPIs across all deliverables.

Sheet Raw_Suppliers
A1: Supplier_ID | B1: Supplier_Name | C1: Country | D1: Region | E1: City | F1: Primary_Category | G1: Onboarded_Date | H1: USMCA_Qualifying
A2: SUP-001 | B2: TitanForge Components | C2: United States | D2: Domestic | E2: Columbus, OH | F2: GPU Servers | G2: 44999
A3: SUP-002 | B3: Bajio Precision Systems | C3: Mexico | D3: Nearshore | E3: Queretaro, MX | F3: Network Switches | G3: 45313 | H3: Y
A4: SUP-003 | B4: Zhongxin Compute Manufacturing | C4: China | D4: Offshore | E4: Shenzhen, CN | F4: PDU / MEP Equipment | G4: 44805

Sheet Raw_POs
A1: PO_ID | B1: Supplier_ID | C1: Product_Category | D1: HS_Code | E1: PO_Date | F1: Quantity | G1: Unit_Cost_USD | H1: Incoterm | I1: Freight_Mode | J1: Promised_Delivery_Date | K1: Actual_Delivery_Date | L1: Customs_Clearance_Days | M1: Defect_Flag | N1: PO_Status | O1: Lead_Time_Days | P1: On_Time_Flag | Q1: Supplier_Country | R1: Tariff_Key | S1: Effective_Tariff_Rate | T1: Base_Spend_USD | U1: Landed_Cost_Per_Unit | V1: Landed_Cost_Total | W1: Is_First_Occurrence
A2: PO-1319 | B2: SUP-001 | C2: PDU / MEP Equipment | D2: 8537.1 | E2: 45663 | F2: 8 | G2: 2982.5 | H2: DDP | I2: Truck | J2: 45679 | K2: 45679 | L2: 1 | M2: N | N2: Delivered | O2: =IF(K2="",0,K2-E2) | P2: =IF(N2<>"Delivered","",IF(K2<=J2,1,0)) | Q2: =IFERROR(INDEX(Raw_Suppliers!$C$2:$C$4,MATCH(B2,Raw_Suppliers!$A$2:$A$4,0)),"") | R2: =Q2&"|"&D2 | S2: =IFERROR(INDEX(Raw_Tariff_Ref!$H$2:$H$10,MATCH(R2,Raw_Tariff_Ref!$I$2:$I$10,0)),0) | T2: =IF(G2="","",G2*F2) | U2: =IF(G2="","",G2*(1+S2)) | V2: =IF(U2="","",U2*F2) | W2: =IF(COUNTIF($A$2:A2,A2)=1,1,0)
A3: PO-1013 | B3: SUP-001 | C3: GPU Servers | D3: 8471.5 | E3: 45663 | F3: 2 | G3: 21585.41 | H3: DDP | I3: Air | J3: 45674 | K3: 45673 | L3: 0 | M3: N | N3: Delivered | O3: =IF(K3="",0,K3-E3) | P3: =IF(N3<>"Delivered","",IF(K3<=J3,1,0)) | Q3: =IFERROR(INDEX(Raw_Suppliers!$C$2:$C$4,MATCH(B3,Raw_Suppliers!$A$2:$A$4,0)),"") | R3: =Q3&"|"&D3 | S3: =IFERROR(INDEX(Raw_Tariff_Ref!$H$2:$H$10,MATCH(R3,Raw_Tariff_Ref!$I$2:$I$10,0)),0) | T3: =IF(G3="","",G3*F3) | U3: =IF(G3="","",G3*(1+S3)) | V3: =IF(U3="","",U3*F3) | W3: =IF(COUNTIF($A$2:A3,A3)=1,1,0)
A4: PO-1012 | B4: SUP-002 | C4: GPU Servers | D4: 8471.5 | E4: 45666 | F4: 25 | G4: 17318.17 | H4: FOB | I4: Ocean | J4: 45689 | K4: 45698 | L4: 2 | M4: N | N4: Delivered | O4: =IF(K4="",0,K4-E4) | P4: =IF(N4<>"Delivered","",IF(K4<=J4,1,0)) | Q4: =IFERROR(INDEX(Raw_Suppliers!$C$2:$C$4,MATCH(B4,Raw_Suppliers!$A$2:$A$4,0)),"") | R4: =Q4&"|"&D4 | S4: =IFERROR(INDEX(Raw_Tariff_Ref!$H$2:$H$10,MATCH(R4,Raw_Tariff_Ref!$I$2:$I$10,0)),0) | T4: =IF(G4="","",G4*F4) | U4: =IF(G4="","",G4*(1+S4)) | V4: =IF(U4="","",U4*F4) | W4: =IF(COUNTIF($A$2:A4,A4)=1,1,0)
A5: PO-1002 | B5: SUP-002 | C5: GPU Servers | D5: 8471.5 | E5: 45669 | F5: 16 | G5: 16525.27 | H5: FOB | I5: Truck | J5: 45686 | K5: 45684 | L5: 3 | M5: N | N5: Delivered | O5: =IF(K5="",0,K5-E5) | P5: =IF(N5<>"Delivered","",IF(K5<=J5,1,0)) | Q5: =IFERROR(INDEX(Raw_Suppliers!$C$2:$C$4,MATCH(B5,Raw_Suppliers!$A$2:$A$4,0)),"") | R5: =Q5&"|"&D5 | S5: =IFERROR(INDEX(Raw_Tariff_Ref!$H$2:$H$10,MATCH(R5,Raw_Tariff_Ref!$I$2:$I$10,0)),0) | T5: =IF(G5="","",G5*F5) | U5: =IF(G5="","",G5*(1+S5)) | V5: =IF(U5="","",U5*F5) | W5: =IF(COUNTIF($A$2:A5,A5)=1,1,0)
A6: PO-1125 | B6: SUP-002 | C6: Network Switches | D6: 8517.62 | E6: 45670 | F6: 5 | G6: 3716.54 | H6: CIF | I6: Ocean | J6: 45692 | K6: 45690 | L6: 1 | M6: N | N6: Delivered | O6: =IF(K6="",0,K6-E6) | P6: =IF(N6<>"Delivered","",IF(K6<=J6,1,0)) | Q6: =IFERROR(INDEX(Raw_Suppliers!$C$2:$C$4,MATCH(B6,Raw_Suppliers!$A$2:$A$4,0)),"") | R6: =Q6&"|"&D6 | S6: =IFERROR(INDEX(Raw_Tariff_Ref!$H$2:$H$10,MATCH(R6,Raw_Tariff_Ref!$I$2:$I$10,0)),0) | T6: =IF(G6="","",G6*F6) | U6: =IF(G6="","",G6*(1+S6)) | V6: =IF(U6="","",U6*F6) | W6: =IF(COUNTIF($A$2:A6,A6)=1,1,0)
A7: PO-1229 | B7: SUP-001 | C7: GPU Servers | D7: 8471.5 | E7: 45672 | F7: 12 | G7: 23435.22 | H7: DDP | I7: Air | J7: 45685 | K7: 45684 | L7: 0 | M7: N | N7: Delivered | O7: =IF(K7="",0,K7-E7) | P7: =IF(N7<>"Delivered","",IF(K7<=J7,1,0)) | Q7: =IFERROR(INDEX(Raw_Suppliers!$C$2:$C$4,MATCH(B7,Raw_Suppliers!$A$2:$A$4,0)),"") | R7: =Q7&"|"&D7 | S7: =IFERROR(INDEX(Raw_Tariff_Ref!$H$2:$H$10,MATCH(R7,Raw_Tariff_Ref!$I$2:$I$10,0)),0) | T7: =IF(G7="","",G7*F7) | U7: =IF(G7="","",G7*(1+S7)) | V7: =IF(U7="","",U7*F7) | W7: =IF(COUNTIF($A$2:A7,A7)=1,1,0)
A8: PO-1230 | B8: SUP-001 | C8: PDU / MEP Equipment | D8: 8537.1 | E8: 45675 | F8: 10 | G8: 3972.18 | H8: DDP | I8: Truck | J8: 45683 | K8: 45683 | L8: 1 | M8: N | N8: Delivered | O8: =IF(K8="",0,K8-E8) | P8: =IF(N8<>"Delivered","",IF(K8<=J8,1,0)) | Q8: =IFERROR(INDEX(Raw_Suppliers!$C$2:$C$4,MATCH(B8,Raw_Suppliers!$A$2:$A$4,0)),"") | R8: =Q8&"|"&D8 | S8: =IFERROR(INDEX(Raw_Tariff_Ref!$H$2:$H$10,MATCH(R8,Raw_Tariff_Ref!$I$2:$I$10,0)),0) | T8: =IF(G8="","",G8*F8) | U8: =IF(G8="","",G8*(1+S8)) | V8: =IF(U8="","",U8*F8) | W8: =IF(COUNTIF($A$2:A8,A8)=1,1,0)
A9: PO-1088 | B9: SUP-001 | C9: PDU / MEP Equipment | D9: 8537.1 | E9: 45678 | F9: 5 | G9: 2844.16 | H9: DDP | I9: Air | J9: 45690 | K9: 45689 | L9: 1 | M9: N | N9: Delivered | O9: =IF(K9="",0,K9-E9) | P9: =IF(N9<>"Delivered","",IF(K9<=J9,1,0)) | Q9: =IFERROR(INDEX(Raw_Suppliers!$C$2:$C$4,MATCH(B9,Raw_Suppliers!$A$2:$A$4,0)),"") | R9: =Q9&"|"&D9 | S9: =IFERROR(INDEX(Raw_Tariff_Ref!$H$2:$H$10,MATCH(R9,Raw_Tariff_Ref!$I$2:$I$10,0)),0) | T9: =IF(G9="","",G9*F9) | U9: =IF(G9="","",G9*(1+S9)) | V9: =IF(U9="","",U9*F9) | W9: =IF(COUNTIF($A$2:A9,A9)=1,1,0)
A10: PO-1154 | B10: SUP-003 | C10: Network Switches | D10: 8517.62 | E10: 45679 | F10: 12 | G10: 1921.59 | H10: CIF | I10: Ocean | J10: 45724 | K10: 45722 | L10: 12 | M10: N | N10: Delivered | O10: =IF(K10="",0,K10-E10) | P10: =IF(N10<>"Delivered","",IF(K10<=J10,1,0)) | Q10: =IFERROR(INDEX(Raw_Suppliers!$C$2:$C$4,MATCH(B10,Raw_Suppliers!$A$2:$A$4,0)),"") | R10: =Q10&"|"&D10 | S10: =IFERROR(INDEX(Raw_Tariff_Ref!$H$2:$H$10,MATCH(R10,Raw_Tariff_Ref!$I$2:$I$10,0)),0) | T10: =IF(G10="","",G10*F10) | U10: =IF(G10="","",G10*(1+S10)) | V10: =IF(U10="","",U10*F10) | W10: =IF(COUNTIF($A$2:A10,A10)=1,1,0)
A11: PO-1287 | B11: SUP-003 | C11: PDU / MEP Equipment | D11: 8537.1 | E11: 45680 | F11: 10 | G11: 2468.63 | H11: EXW | I11: Air | J11: 45704 | K11: 45702 | L11: 11 | M11: N | N11: Delivered | O11: =IF(K11="",0,K11-E11) | P11: =IF(N11<>"Delivered","",IF(K11<=J11,1,0)) | Q11: =IFERROR(INDEX(Raw_Suppliers!$C$2:$C$4,MATCH(B11,Raw_Suppliers!$A$2:$A$4,0)),"") | R11: =Q11&"|"&D11 | S11: =IFERROR(INDEX(Raw_Tariff_Ref!$H$2:$H$10,MATCH(R11,Raw_Tariff_Ref!$I$2:$I$10,0)),0) | T11: =IF(G11="","",G11*F11) | U11: =IF(G11="","",G11*(1+S11)) | V11: =IF(U11="","",U11*F11) | W11: =IF(COUNTIF($A$2:A11,A11)=1,1,0)
A12: PO-1314 | B12: SUP-002 | C12: Network Switches | D12: 8517.62 | E12: 45682 | F12: 20 | G12: 3806.87 | H12: CIF | I12: Ocean | J12: 45697 | K12: 45709 | L12: 3 | M12: N | N12: Delivered | O12: =IF(K12="",0,K12-E12) | P12: =IF(N12<>"Delivered","",IF(K12<=J12,1,0)) | Q12: =IFERROR(INDEX(Raw_Suppliers!$C$2:$C$4,MATCH(B12,Raw_Suppliers!$A$2:$A$4,0)),"") | R12: =Q12&"|"&D12 | S12: =IFERROR(INDEX(Raw_Tariff_Ref!$H$2:$H$10,MATCH(R12,Raw_Tariff_Ref!$I$2:$I$10,0)),0) | T12: =IF(G12="","",G12*F12) | U12: =IF(G12="","",G12*(1+S12)) | V12: =IF(U12="","",U12*F12) | W12: =IF(COUNTIF($A$2:A12,A12)=1,1,0)
A13: PO-1128 | B13: SUP-001 | C13: PDU / MEP Equipment | D13: 8537.1 | E13: 45684 | F13: 40 | G13: 3716.76 | H13: DDP | I13: Truck | J13: 45697 | K13: 45703 | L13: 1 | M13: N | N13: Delivered | O13: =IF(K13="",0,K13-E13) | P13: =IF(N13<>"Delivered","",IF(K13<=J13,1,0)) | Q13: =IFERROR(INDEX(Raw_Suppliers!$C$2:$C$4,MATCH(B13,Raw_Suppliers!$A$2:$A$4,0)),"") | R13: =Q13&"|"&D13 | S13: =IFERROR(INDEX(Raw_Tariff_Ref!$H$2:$H$10,MATCH(R13,Raw_Tariff_Ref!$I$2:$I$10,0)),0) | T13: =IF(G13="","",G13*F13) | U13: =IF(G13="","",G13*(1+S13)) | V13: =IF(U13="","",U13*F13) | W13: =IF(COUNTIF($A$2:A13,A13)=1,1,0)
... A29: PO-1275 | B29: SUP-003 | C29: PDU / MEP Equipment | D29: 8537.1 | E29: 45710 | F29: 2 | G29: 2297.91 | H29: EXW | I29: Air | J29: 45742 | K29: 45741 | L29: 10 | M29: N | N29: Delivered | O29: =IF(K29="",0,K29-E29) | P29: =IF(N29<>"Delivered","",IF(K29<=J29,1,0)) | Q29: =IFERROR(INDEX(Raw_Suppliers!$C$2:$C$4,MATCH(B29,Raw_Suppliers!$A$2:$A$4,0)),"") | R29: =Q29&"|"&D29 | S29: =IFERROR(INDEX(Raw_Tariff_Ref!$H$2:$H$10,MATCH(R29,Raw_Tariff_Ref!$I$2:$I$10,0)),0) | T29: =IF(G29="","",G29*F29) | U29: =IF(G29="","",G29*(1+S29)) | V29: =IF(U29="","",U29*F29) | W29: =IF(COUNTIF($A$2:A29,A29)=1,1,0)
A30: PO-1118 | B30: SUP-002 | C30: GPU Servers | D30: 8471.5 | E30: 45715 | F30: 10 | H30: fob | I30: Truck | J30: 45733 | K30: 45753 | L30: 4 | M30: N | N30: Delivered | O30: =IF(K30="",0,K30-E30) | P30: =IF(N30<>"Delivered","",IF(K30<=J30,1,0)) | Q30: =IFERROR(INDEX(Raw_Suppliers!$C$2:$C$4,MATCH(B30,Raw_Suppliers!$A$2:$A$4,0)),"") | R30: =Q30&"|"&D30 | S30: =IFERROR(INDEX(Raw_Tariff_Ref!$H$2:$H$10,MATCH(R30,Raw_Tariff_Ref!$I$2:$I$10,0)),0) | T30: =IF(G30="","",G30*F30) | U30: =IF(G30="","",G30*(1+S30)) | V30: =IF(U30="","",U30*F30) | W30: =IF(COUNTIF($A$2:A30,A30)=1,1,0)
A31: PO-1019 | B31: SUP-002 | C31: GPU Servers | D31: 8471.5 | E31: 45718 | F31: 4 | G31: 21292.19 | H31: CIF | I31: Truck | J31: 45731 | K31: 45731 | L31: 2 | M31: N | N31: Delivered | O31: =IF(K31="",0,K31-E31) | P31: =IF(N31<>"Delivered","",IF(K31<=J31,1,0)) | Q31: =IFERROR(INDEX(Raw_Suppliers!$C$2:$C$4,MATCH(B31,Raw_Suppliers!$A$2:$A$4,0)),"") | R31: =Q31&"|"&D31 | S31: =IFERROR(INDEX(Raw_Tariff_Ref!$H$2:$H$10,MATCH(R31,Raw_Tariff_Ref!$I$2:$I$10,0)),0) | T31: =IF(G31="","",G31*F31) | U31: =IF(G31="","",G31*(1+S31)) | V31: =IF(U31="","",U31*F31) | W31: =IF(COUNTIF($A$2:A31,A31)=1,1,0)
A32: PO-1133 | B32: SUP-003 | C32: Network Switches | D32: 8517.62 | E32: 45720 | F32: 10 | G32: 1953.91 | H32: EXW | I32: Ocean | J32: 45751 | K32: 45749 | L32: 8 | M32: N | N32: Delivered | O32: =IF(K32="",0,K32-E32) | P32: =IF(N32<>"Delivered","",IF(K32<=J32,1,0)) | Q32: =IFERROR(INDEX(Raw_Suppliers!$C$2:$C$4,MATCH(B32,Raw_Suppliers!$A$2:$A$4,0)),"") | R32: =Q32&"|"&D32 | S32: =IFERROR(INDEX(Raw_Tariff_Ref!$H$2:$H$10,MATCH(R32,Raw_Tariff_Ref!$I$2:$I$10,0)),0) | T32: =IF(G32="","",G32*F32) | U32: =IF(G32="","",G32*(1+S32)) | V32: =IF(U32="","",U32*F32) | W32: =IF(COUNTIF($A$2:A32,A32)=1,1,0)
A33: PO-1290 | B33: SUP-003 | C33: PDU / MEP Equipment | D33: 8537.1 | E33: 45722 | F33: 4 | G33: 2104.21 | H33: CIF | I33: Ocean | J33: 45756 | K33: 45755 | L33: 7 | M33: N | N33: Delivered | O33: =IF(K33="",0,K33-E33) | P33: =IF(N33<>"Delivered","",IF(K33<=J33,1,0)) | Q33: =IFERROR(INDEX(Raw_Suppliers!$C$2:$C$4,MATCH(B33,Raw_Suppliers!$A$2:$A$4,0)),"") | R33: =Q33&"|"&D33 | S33: =IFERROR(INDEX(Raw_Tariff_Ref!$H$2:$H$10,MATCH(R33,Raw_Tariff_Ref!$I$2:$I$10,0)),0) | T33: =IF(G33="","",G33*F33) | U33: =IF(G33="","",G33*(1+S33)) | V33: =IF(U33="","",U33*F33) | W33: =IF(COUNTIF($A$2:A33,A33)=1,1,0)
A34: PO-1270 | B34: SUP-003 | C34: Network Switches | D34: 8517.62 | E34: 45723 | F34: 5 | G34: 1958.97 | H34: CIF | I34: Air | J34: 45774 | K34: 45784 | L34: 6 | M34: N | N34: Delivered | O34: =IF(K34="",0,K34-E34) | P34: =IF(N34<>"Delivered","",IF(K34<=J34,1,0)) | Q34: =IFERROR(INDEX(Raw_Suppliers!$C$2:$C$4,MATCH(B34,Raw_Suppliers!$A$2:$A$4,0)),"") | R34: =Q34&"|"&D34 | S34: =IFERROR(INDEX(Raw_Tariff_Ref!$H$2:$H$10,MATCH(R34,Raw_Tariff_Ref!$I$2:$I$10,0)),0) | T34: =IF(G34="","",G34*F34) | U34: =IF(G34="","",G34*(1+S34)) | V34: =IF(U34="","",U34*F34) | W34: =IF(COUNTIF($A$2:A34,A34)=1,1,0)
A35: PO-1228 | B35: SUP-003 | C35: GPU Servers | D35: 8471.5 | E35: 45723 | F35: 2 | G35: 17172.45 | H35: FOB | I35: Ocean | J35: 45748 | K35: 45746 | L35: 6 | M35: N | N35: Delivered | O35: =IF(K35="",0,K35-E35) | P35: =IF(N35<>"Delivered","",IF(K35<=J35,1,0)) | Q35: =IFERROR(INDEX(Raw_Suppliers!$C$2:$C$4,MATCH(B35,Raw_Suppliers!$A$2:$A$4,0)),"") | R35: =Q35&"|"&D35 | S35: =IFERROR(INDEX(Raw_Tariff_Ref!$H$2:$H$10,MATCH(R35,Raw_Tariff_Ref!$I$2:$I$10,0)),0) | T35: =IF(G35="","",G35*F35) | U35: =IF(G35="","",G35*(1+S35)) | V35: =IF(U35="","",U35*F35) | W35: =IF(COUNTIF($A$2:A35,A35)=1,1,0)
A36: PO-1112 | B36: SUP-003 | C36: PDU / MEP Equipment | D36: 8537.1 | E36: 45725 | F36: 16 | G36: 1418.55 | H36: FOB | I36: Air | J36: 45756 | K36: 45783 | L36: 4 | M36: N | N36: Delivered | O36: =IF(K36="",0,K36-E36) | P36: =IF(N36<>"Delivered","",IF(K36<=J36,1,0)) | Q36: =IFERROR(INDEX(Raw_Suppliers!$C$2:$C$4,MATCH(B36,Raw_Suppliers!$A$2:$A$4,0)),"") | R36: =Q36&"|"&D36 | S36: =IFERROR(INDEX(Raw_Tariff_Ref!$H$2:$H$10,MATCH(R36,Raw_Tariff_Ref!$I$2:$I$10,0)),0) | T36: =IF(G36="","",G36*F36) | U36: =IF(G36="","",G36*(1+S36)) | V36: =IF(U36="","",U36*F36) | W36: =IF(COUNTIF($A$2:A36,A36)=1,1,0)
A37: PO-1206 | B37: SUP-003 | C37: PDU / MEP Equipment | D37: 8537.1 | E37: 45726 | F37: 8 | G37: 2332.58 | H37: EXW | I37: Ocean | J37: 45753 | K37: 45787 | L37: 8 | M37: N | N37: Delivered | O37: =IF(K37="",0,K37-E37) | P37: =IF(N37<>"Delivered","",IF(K37<=J37,1,0)) | Q37: =IFERROR(INDEX(Raw_Suppliers!$C$2:$C$4,MATCH(B37,Raw_Suppliers!$A$2:$A$4,0)),"") | R37: =Q37&"|"&D37 | S37: =IFERROR(INDEX(Raw_Tariff_Ref!$H$2:$H$10,MATCH(R37,Raw_Tariff_Ref!$I$2:$I$10,0)),0) | T37: =IF(G37="","",G37*F37) | U37: =IF(G37="","",G37*(1+S37)) | V37: =IF(U37="","",U37*F37) | W37: =IF(COUNTIF($A$2:A37,A37)=1,1,0)
A38: PO-1156 | B38: SUP-003 | C38: PDU / MEP Equipment | D38: 8537.1 | E38: 45727 | F38: 2 | G38: 1969.01 | H38: EXW | I38: Ocean | J38: 45764 | K38: 45795 | L38: 3 | M38: N | N38: Delivered | O38: =IF(K38="",0,K38-E38) | P38: =IF(N38<>"Delivered","",IF(K38<=J38,1,0)) | Q38: =IFERROR(INDEX(Raw_Suppliers!$C$2:$C$4,MATCH(B38,Raw_Suppliers!$A$2:$A$4,0)),"") | R38: =Q38&"|"&D38 | S38: =IFERROR(INDEX(Raw_Tariff_Ref!$H$2:$H$10,MATCH(R38,Raw_Tariff_Ref!$I$2:$I$10,0)),0) | T38: =IF(G38="","",G38*F38) | U38: =IF(G38="","",G38*(1+S38)) | V38: =IF(U38="","",U38*F38) | W38: =IF(COUNTIF($A$2:A38,A38)=1,1,0)
A39: PO-1016 | B39: SUP-001 | C39: GPU Servers | D39: 8471.5 | E39: 45728 | F39: 25 | G39: 22605.4 | H39: FOB | I39: Truck | J39: 45738 | K39: 45738 | L39: 0 | M39: N | N39: Delivered | O39: =IF(K39="",0,K39-E39) | P39: =IF(N39<>"Delivered","",IF(K39<=J39,1,0)) | Q39: =IFERROR(INDEX(Raw_Suppliers!$C$2:$C$4,MATCH(B39,Raw_Suppliers!$A$2:$A$4,0)),"") | R39: =Q39&"|"&D39 | S39: =IFERROR(INDEX(Raw_Tariff_Ref!$H$2:$H$10,MATCH(R39,Raw_Tariff_Ref!$I$2:$I$10,0)),0) | T39: =IF(G39="","",G39*F39) | U39: =IF(G39="","",G39*(1+S39)) | V39: =IF(U39="","",U39*F39) | W39: =IF(COUNTIF($A$2:A39,A39)=1,1,0)
A40: PO-1221 | B40: SUP-002 | C40: Network Switches | D40: 8517.62 | E40: 45737 | F40: 25 | G40: 4992.43 | H40: FOB | I40: Ocean | J40: 45751 | K40: 45751 | L40: 3 | M40: N | N40: Delivered | O40: =IF(K40="",0,K40-E40) | P40: =IF(N40<>"Delivered","",IF(K40<=J40,1,0)) | Q40: =IFERROR(INDEX(Raw_Suppliers!$C$2:$C$4,MATCH(B40,Raw_Suppliers!$A$2:$A$4,0)),"") | R40: =Q40&"|"&D40 | S40: =IFERROR(INDEX(Raw_Tariff_Ref!$H$2:$H$10,MATCH(R40,Raw_Tariff_Ref!$I$2:$I$10,0)),0) | T40: =IF(G40="","",G40*F40) | U40: =IF(G40="","",G40*(1+S40)) | V40: =IF(U40="","",U40*F40) | W40: =IF(COUNTIF($A$2:A40,A40)=1,1,0)
A41: PO-1044 | B41: SUP-001 | C41: PDU / MEP Equipment | D41: 8537.1 | E41: 45737 | F41: 40 | G41: 3193.19 | H41: DDP | I41: Air | J41: 45748 | K41: 45748 | L41: 1 | M41: N | N41: Delivered | O41: =IF(K41="",0,K41-E41) | P41: =IF(N41<>"Delivered","",IF(K41<=J41,1,0)) | Q41: =IFERROR(INDEX(Raw_Suppliers!$C$2:$C$4,MATCH(B41,Raw_Suppliers!$A$2:$A$4,0)),"") | R41: =Q41&"|"&D41 | S41: =IFERROR(INDEX(Raw_Tariff_Ref!$H$2:$H$10,MATCH(R41,Raw_Tariff_Ref!$I$2:$I$10,0)),0) | T41: =IF(G41="","",G41*F41) | U41: =IF(G41="","",G41*(1+S41)) | V41: =IF(U41="","",U41*F41) | W41: =IF(COUNTIF($A$2:A41,A41)=1,1,0)
A42: PO-1303 | B42: SUP-001 | C42: PDU / MEP Equipment | D42: 8537.1 | E42: 45739 | F42: 16 | G42: 3844.46 | H42: FOB | I42: Truck | J42: 45748 | K42: 45746 | L42: 1 | M42: N | N42: Delivered | O42: =IF(K42="",0,K42-E42) | P42: =IF(N42<>"Delivered","",IF(K42<=J42,1,0)) | Q42: =IFERROR(INDEX(Raw_Suppliers!$C$2:$C$4,MATCH(B42,Raw_Suppliers!$A$2:$A$4,0)),"") | R42: =Q42&"|"&D42 | S42: =IFERROR(INDEX(Raw_Tariff_Ref!$H$2:$H$10,MATCH(R42,Raw_Tariff_Ref!$I$2:$I$10,0)),0) | T42: =IF(G42="","",G42*F42) | U42: =IF(G42="","",G42*(1+S42)) | V42: =IF(U42="","",U42*F42) | W42: =IF(COUNTIF($A$2:A42,A42)=1,1,0)
... A53: PO-1136 | B53: SUP-003 | C53: Network Switches | D53: 8517.62 | E53: 45749 | F53: 2 | G53: 2090.59 | H53: FOB | I53: Air | J53: 45778 | K53: 45776 | L53: 11 | M53: N | N53: Delivered | O53: =IF(K53="",0,K53-E53) | P53: =IF(N53<>"Delivered","",IF(K53<=J53,1,0)) | Q53: =IFERROR(INDEX(Raw_Suppliers!$C$2:$C$4,MATCH(B53,Raw_Suppliers!$A$2:$A$4,0)),"") | R53: =Q53&"|"&D53 | S53: =IFERROR(INDEX(Raw_Tariff_Ref!$H$2:$H$10,MATCH(R53,Raw_Tariff_Ref!$I$2:$I$10,0)),0) | T53: =IF(G53="","",G53*F53) | U53: =IF(G53="","",G53*(1+S53)) | V53: =IF(U53="","",U53*F53) | W53: =IF(COUNTIF($A$2:A53,A53)=1,1,0)
A54: PO-1251 | B54: SUP-002 | C54: GPU Servers | D54: 8471.5 | E54: 45750 | F54: 12 | H54: FOB | I54: Ocean | J54: 45773 | K54: 45771 | L54: 3 | M54: N | N54: Delivered | O54: =IF(K54="",0,K54-E54) | P54: =IF(N54<>"Delivered","",IF(K54<=J54,1,0)) | Q54: =IFERROR(INDEX(Raw_Suppliers!$C$2:$C$4,MATCH(B54,Raw_Suppliers!$A$2:$A$4,0)),"") | R54: =Q54&"|"&D54 | S54: =IFERROR(INDEX(Raw_Tariff_Ref!$H$2:$H$10,MATCH(R54,Raw_Tariff_Ref!$I$2:$I$10,0)),0) | T54: =IF(G54="","",G54*F54) | U54: =IF(G54="","",G54*(1+S54)) | V54: =IF(U54="","",U54*F54) | W54: =IF(COUNTIF($A$2:A54,A54)=1,1,0)
A55: PO-1239 | B55: SUP-001 | C55: PDU / MEP Equipment | D55: 8537.1 | E55: 45750 | F55: 8 | G55: 3995.05 | H55: FOB | I55: Air | J55: 45762 | K55: 45761 | L55: 0 | M55: N | N55: Delivered | O55: =IF(K55="",0,K55-E55) | P55: =IF(N55<>"Delivered","",IF(K55<=J55,1,0)) | Q55: =IFERROR(INDEX(Raw_Suppliers!$C$2:$C$4,MATCH(B55,Raw_Suppliers!$A$2:$A$4,0)),"") | R55: =Q55&"|"&D55 | S55: =IFERROR(INDEX(Raw_Tariff_Ref!$H$2:$H$10,MATCH(R55,Raw_Tariff_Ref!$I$2:$I$10,0)),0) | T55: =IF(G55="","",G55*F55) | U55: =IF(G55="","",G55*(1+S55)) | V55: =IF(U55="","",U55*F55) | W55: =IF(COUNTIF($A$2:A55,A55)=1,1,0)
A56: PO-1063 | B56: SUP-002 | C56: Network Switches | D56: 8517.62 | E56: 45750 | F56: 20 | G56: 4576.34 | H56: FOB | I56: Ocean | J56: 45769 | K56: 45768 | L56: 4 | M56: N | N56: Delivered | O56: =IF(K56="",0,K56-E56) | P56: =IF(N56<>"Delivered","",IF(K56<=J56,1,0)) | Q56: =IFERROR(INDEX(Raw_Suppliers!$C$2:$C$4,MATCH(B56,Raw_Suppliers!$A$2:$A$4,0)),"") | R56: =Q56&"|"&D56 | S56: =IFERROR(INDEX(Raw_Tariff_Ref!$H$2:$H$10,MATCH(R56,Raw_Tariff_Ref!$I$2:$I$10,0)),0) | T56: =IF(G56="","",G56*F56) | U56: =IF(G56="","",G56*(1+S56)) | V56: =IF(U56="","",U56*F56) | W56: =IF(COUNTIF($A$2:A56,A56)=1,1,0)
A57: PO-1014 | B57: SUP-001 | C57: GPU Servers | D57: 8471.5 | E57: 45750 | F57: 25 | G57: 22145.27 | H57: FOB | I57: Air | J57: 45760 | K57: 45758 | L57: 0 | M57: N | N57: Delivered | O57: =IF(K57="",0,K57-E57) | P57: =IF(N57<>"Delivered","",IF(K57<=J57,1,0)) | Q57: =IFERROR(INDEX(Raw_Suppliers!$C$2:$C$4,MATCH(B57,Raw_Suppliers!$A$2:$A$4,0)),"") | R57: =Q57&"|"&D57 | S57: =IFERROR(INDEX(Raw_Tariff_Ref!$H$2:$H$10,MATCH(R57,Raw_Tariff_Ref!$I$2:$I$10,0)),0) | T57: =IF(G57="","",G57*F57) | U57: =IF(G57="","",G57*(1+S57)) | V57: =IF(U57="","",U57*F57) | W57: =IF(COUNTIF($A$2:A57,A57)=1,1,0)
A58: PO-1331 | B58: SUP-002 | C58: GPU Servers | D58: 8471.5 | E58: 45752 | F58: 40 | G58: 20772.96 | H58: FOB | I58: Truck | J58: 45768 | K58: 45768 | L58: 2 | M58: N | N58: Delivered | O58: =IF(K58="",0,K58-E58) | P58: =IF(N58<>"Delivered","",IF(K58<=J58,1,0)) | Q58: =IFERROR(INDEX(Raw_Suppliers!$C$2:$C$4,MATCH(B58,Raw_Suppliers!$A$2:$A$4,0)),"") | R58: =Q58&"|"&D58 | S58: =IFERROR(INDEX(Raw_Tariff_Ref!$H$2:$H$10,MATCH(R58,Raw_Tariff_Ref!$I$2:$I$10,0)),0) | T58: =IF(G58="","",G58*F58) | U58: =IF(G58="","",G58*(1+S58)) | V58: =IF(U58="","",U58*F58) | W58: =IF(COUNTIF($A$2:A58,A58)=1,1,0)
A59: PO-1134 | B59: SUP-003 | C59: PDU / MEP Equipment | D59: 8537.1 | E59: 45755 | F59: 16 | G59: 1743.85 | H59: CIF | I59: Ocean | J59: 45809 | K59: 45809 | L59: 10 | M59: N | N59: Delivered | O59: =IF(K59="",0,K59-E59) | P59: =IF(N59<>"Delivered","",IF(K59<=J59,1,0)) | Q59: =IFERROR(INDEX(Raw_Suppliers!$C$2:$C$4,MATCH(B59,Raw_Suppliers!$A$2:$A$4,0)),"") | R59: =Q59&"|"&D59 | S59: =IFERROR(INDEX(Raw_Tariff_Ref!$H$2:$H$10,MATCH(R59,Raw_Tariff_Ref!$I$2:$I$10,0)),0) | T59: =IF(G59="","",G59*F59) | U59: =IF(G59="","",G59*(1+S59)) | V59: =IF(U59="","",U59*F59) | W59: =IF(COUNTIF($A$2:A59,A59)=1,1,0)
A60: PO-1090 | B60: SUP-003 | C60: GPU Servers | D60: 8471.5 | E60: 45755 | F60: 4 | G60: 17058.01 | H60: CIF | I60: Air | J60: 45793 | K60: 45791 | L60: 3 | M60: N | N60: Delivered | O60: =IF(K60="",0,K60-E60) | P60: =IF(N60<>"Delivered","",IF(K60<=J60,1,0)) | Q60: =IFERROR(INDEX(Raw_Suppliers!$C$2:$C$4,MATCH(B60,Raw_Suppliers!$A$2:$A$4,0)),"") | R60: =Q60&"|"&D60 | S60: =IFERROR(INDEX(Raw_Tariff_Ref!$H$2:$H$10,MATCH(R60,Raw_Tariff_Ref!$I$2:$I$10,0)),0) | T60: =IF(G60="","",G60*F60) | U60: =IF(G60="","",G60*(1+S60)) | V60: =IF(U60="","",U60*F60) | W60: =IF(COUNTIF($A$2:A60,A60)=1,1,0)
A61: PO-1082 | B61: SUP-002 | C61: GPU Servers | D61: 8471.5 | E61: 45758 | F61: 20 | G61: 21378.28 | H61: FOB | I61: Ocean | J61: 45772 | K61: 45770 | L61: 3 | M61: N | N61: Delivered | O61: =IF(K61="",0,K61-E61) | P61: =IF(N61<>"Delivered","",IF(K61<=J61,1,0)) | Q61: =IFERROR(INDEX(Raw_Suppliers!$C$2:$C$4,MATCH(B61,Raw_Suppliers!$A$2:$A$4,0)),"") | R61: =Q61&"|"&D61 | S61: =IFERROR(INDEX(Raw_Tariff_Ref!$H$2:$H$10,MATCH(R61,Raw_Tariff_Ref!$I$2:$I$10,0)),0) | T61: =IF(G61="","",G61*F61) | U61: =IF(G61="","",G61*(1+S61)) | V61: =IF(U61="","",U61*F61) | W61: =IF(COUNTIF($A$2:A61,A61)=1,1,0)
A62: PO-1140 | B62: SUP-003 | C62: GPU Servers | D62: 8471.5 | E62: 45758 | F62: 25 | G62: 15395.05 | H62: FOB | I62: Air | J62: 45792 | K62: 45791 | L62: 5 | M62: N | N62: Delivered | O62: =IF(K62="",0,K62-E62) | P62: =IF(N62<>"Delivered","",IF(K62<=J62,1,0)) | Q62: =IFERROR(INDEX(Raw_Suppliers!$C$2:$C$4,MATCH(B62,Raw_Suppliers!$A$2:$A$4,0)),"") | R62: =Q62&"|"&D62 | S62: =IFERROR(INDEX(Raw_Tariff_Ref!$H$2:$H$10,MATCH(R62,Raw_Tariff_Ref!$I$2:$I$10,0)),0) | T62: =IF(G62="","",G62*F62) | U62: =IF(G62="","",G62*(1+S62)) | V62: =IF(U62="","",U62*F62) | W62: =IF(COUNTIF($A$2:A62,A62)=1,1,0)
A63: PO-1064 | B63: SUP-002 | C63: Network Switches | D63: 8517.62 | E63: 45758 | F63: 8 | G63: 5121.14 | H63: CIF | I63: Ocean | J63: 45777 | K63: 45776 | L63: 3 | M63: N | N63: Delivered | O63: =IF(K63="",0,K63-E63) | P63: =IF(N63<>"Delivered","",IF(K63<=J63,1,0)) | Q63: =IFERROR(INDEX(Raw_Suppliers!$C$2:$C$4,MATCH(B63,Raw_Suppliers!$A$2:$A$4,0)),"") | R63: =Q63&"|"&D63 | S63: =IFERROR(INDEX(Raw_Tariff_Ref!$H$2:$H$10,MATCH(R63,Raw_Tariff_Ref!$I$2:$I$10,0)),0) | T63: =IF(G63="","",G63*F63) | U63: =IF(G63="","",G63*(1+S63)) | V63: =IF(U63="","",U63*F63) | W63: =IF(COUNTIF($A$2:A63,A63)=1,1,0)
A64: PO-1117 | B64: SUP-001 | C64: GPU Servers | D64: 8471.5 | E64: 45758 | F64: 12 | G64: 20401.53 | H64: FOB | I64: Air | J64: 45765 | K64: 45765 | L64: 0 | M64: N | N64: Delivered | O64: =IF(K64="",0,K64-E64) | P64: =IF(N64<>"Delivered","",IF(K64<=J64,1,0)) | Q64: =IFERROR(INDEX(Raw_Suppliers!$C$2:$C$4,MATCH(B64,Raw_Suppliers!$A$2:$A$4,0)),"") | R64: =Q64&"|"&D64 | S64: =IFERROR(INDEX(Raw_Tariff_Ref!$H$2:$H$10,MATCH(R64,Raw_Tariff_Ref!$I$2:$I$10,0)),0) | T64: =IF(G64="","",G64*F64) | U64: =IF(G64="","",G64*(1+S64)) | V64: =IF(U64="","",U64*F64) | W64: =IF(COUNTIF($A$2:A64,A64)=1,1,0)
A65: PO-1242 | B65: SUP-001 | C65: PDU / MEP Equipment | D65: 8537.1 | E65: 45758 | F65: 16 | G65: 2634.42 | H65: DDP | I65: Air | J65: 45770 | K65: 45769 | L65: 0 | M65: Y | N65: Delivered | O65: =IF(K65="",0,K65-E65) | P65: =IF(N65<>"Delivered","",IF(K65<=J65,1,0)) | Q65: =IFERROR(INDEX(Raw_Suppliers!$C$2:$C$4,MATCH(B65,Raw_Suppliers!$A$2:$A$4,0)),"") | R65: =Q65&"|"&D65 | S65: =IFERROR(INDEX(Raw_Tariff_Ref!$H$2:$H$10,MATCH(R65,Raw_Tariff_Ref!$I$2:$I$10,0)),0) | T65: =IF(G65="","",G65*F65) | U65: =IF(G65="","",G65*(1+S65)) | V65: =IF(U65="","",U65*F65) | W65: =IF(COUNTIF($A$2:A65,A65)=1,1,0)
...

Sheet Raw_Tariff_Ref
A1: Country | B1: HS_Code | C1: Product_Category | D1: Base_MFN_Rate | E1: Section_301_Rate | F1: Section_122_Surcharge | G1: USMCA_Qualifying | H1: Base_Effective_Rate | I1: Key
A2: United States | B2: 8471.5 | C2: GPU Servers | D2: 0 | E2: 0 | F2: 0 | H2: 0 | I2: =A2&"|"&B2
A3: United States | B3: 8517.62 | C3: Network Switches | D3: 0 | E3: 0 | F3: 0 | H3: 0 | I3: =A3&"|"&B3
A4: United States | B4: 8537.1 | C4: PDU / MEP Equipment | D4: 0 | E4: 0 | F4: 0 | H4: 0 | I4: =A4&"|"&B4
A5: Mexico | B5: 8471.5 | C5: GPU Servers | D5: 0 | E5: 0 | F5: 0 | G5: Y | H5: 0 | I5: =A5&"|"&B5
A6: Mexico | B6: 8517.62 | C6: Network Switches | D6: 0 | E6: 0 | F6: 0 | G6: Y | H6: 0 | I6: =A6&"|"&B6
A7: Mexico | B7: 8537.1 | C7: PDU / MEP Equipment | D7: 0.025 | E7: 0 | F7: 0 | G7: N | H7: 0.025 | I7: =A7&"|"&B7
A8: China | B8: 8471.5 | C8: GPU Servers | D8: 0 | E8: 0.25 | F8: 0.1 | H8: 0.35 | I8: =A8&"|"&B8
A9: China | B9: 8517.62 | C9: Network Switches | D9: 0 | E9: 0.25 | F9: 0.1 | H9: 0.35 | I9: =A9&"|"&B9
A10: China | B10: 8537.1 | C10: PDU / MEP Equipment | D10: 0 | E10: 0.25 | F10: 0.1 | H10: 0.35 | I10: =A10&"|"&B10

Sheet Raw_Tariff_Scenarios
A1: Scenario_Name | B1: Adjustment_Type | C1: Adjustment_Value | D1: Description
A2: Current (Jul 2026) | B2: Additive | C2: 0 | D2: Baseline tariff rates: China ~35%, Mexico ~0%, US 0%
A3: +10% escalation | B3: Additive | C3: 0.1 | D3: Moderate trade tension escalation (+10% tariff on offshore/nearshore non-US origins)
A4: +25% escalation | B4: Additive | C4: 0.25 | D4: Aggressive trade penalty increase (+25% across foreign sourcing)
A5: Section 122 sunset (China -10pt) | B5: Additive | C5: -0.1 | D5: Statutory sunset of Section 122 surcharge on China (-10% effective)
A6: Universal 50% (worst case) | B6: Absolute | C6: 0.5 | D6: Universal blanket tariff rate of 50% on all foreign imports

Sheet Raw_Defects
A1: Defect_ID | B1: PO_ID | C1: Supplier_ID | D1: Defect_Type | E1: Defect_Qty | F1: Detected_Date | G1: Resolution
A2: DEF-0001 | B2: PO-1095 | C2: SUP-001 | D2: Packaging Damage | E2: 1 | F2: 45707 | G2: Returned
A3: DEF-0002 | B3: PO-1242 | C3: SUP-001 | D3: Packaging Damage | E3: 1 | F3: 45769 | G3: Returned
A4: DEF-0003 | B4: PO-1001 | C4: SUP-002 | D4: Cosmetic Damage | E4: 3 | F4: 45775 | G4: Returned
A5: DEF-0004 | B5: PO-1057 | C5: SUP-001 | D5: Packaging Damage | E5: 3 | F5: 45847 | G5: Replaced
A6: DEF-0005 | B6: PO-1329 | C6: SUP-003 | D6: Cosmetic Damage | E6: 1 | F6: 45861 | G6: Pending
A7: DEF-0006 | B7: PO-1017 | C7: SUP-003 | D7: Packaging Damage | E7: 1 | F7: 45928 | G7: Replaced
A8: DEF-0007 | B8: PO-1086 | C8: SUP-003 | D8: Functional Failure | E8: 1 | F8: 45927 | G8: Pending
A9: DEF-0008 | B9: PO-1214 | C9: SUP-002 | D9: Wrong Item Shipped | E9: 6 | F9: 45927 | G9: Returned
A10: DEF-0009 | B10: PO-1195 | C10: SUP-001 | D10: Functional Failure | E10: 1 | F10: 46012 | G10: Replaced
A11: DEF-0010 | B11: PO-1089 | C11: SUP-003 | D11: Wrong Item Shipped | E11: 2 | F11: 46131 | G11: Pending
A12: DEF-0011 | B12: PO-1240 | C12: SUP-002 | D12: Wrong Item Shipped | E12: 1 | F12: 46079 | G12: Replaced
A13: DEF-0012 | B13: PO-1076 | C13: SUP-001 | D13: Functional Failure | E13: 1 | F13: 46115 | G13: Replaced
... A17: DEF-0016 | B17: PO-1318 | C17: SUP-002 | D17: DOA - Dead on Arrival | E17: 3 | F17: 46185 | G17: Credited
